#VRML_SIM R2023b utf8
PROTO FourWheelsRobot [
  field SFVec3f    translation  0 0 0.04
  field SFRotation rotation     0 0 1 0
  field SFFloat    bodyMass     1
  field SFNode     controller   NULL
]
{
  Robot {
    translation IS translation
    rotation IS rotation
    children [
        DistanceSensor {
        translation 0.1 0.03 0
        rotation 0 0 1 0.3
        children [
            Shape {
            geometry DEF DS Box {
                size 0.01 0.01 0.01
            }
            }
        ]
        name "ds_left"
        boundingObject USE DS
        physics Physics {
            mass IS bodyMass
        }
        }
        DistanceSensor {
        translation 0.1 -0.03 0
        rotation 0 0 1 -0.3
        children [
            Shape {
            geometry DEF DS Box {
                size 0.01 0.01 0.01
            }
            }
        ]
        name "ds_right"
        boundingObject USE DS
        physics Physics {
        }
        }
        DEF BODY Shape {
        appearance PBRAppearance {
            baseColor 0.7 0 0
            roughness 1
            metalness 0
        }
        geometry Box {
            size 0.2 0.1 0.05
        }
        }
        HingeJoint {
        jointParameters HingeJointParameters {
            axis 0 1 0
            anchor 0.05 0.06 0
        }
        device [
            RotationalMotor {
            name "wheel1"
            }
        ]
        endPoint DEF Wheel1 Solid {
            translation 0.05 0.06 0
            rotation 1 0 0 1.5707996938995747
            children [
            DEF WHEEL Shape {
                appearance PBRAppearance {
                baseColor 0 0.8 0
                roughness 1
                metalness 0
                }
                geometry Cylinder {
                height 0.02
                radius 0.04
                }
            }
            ]
            boundingObject USE WHEEL
            physics DEF WHEEL_PH Physics {
            }
        }
        }
        HingeJoint {
        jointParameters HingeJointParameters {
            axis 0 1 0
            anchor 0.05 -0.06 0
        }
        device [
            RotationalMotor {
            name "wheel2"
            }
        ]
        endPoint DEF Wheel2 Solid {
            translation 0.05 -0.06 0
            rotation 1 0 0 1.5707996938995747
            children [
            DEF WHEEL Shape {
                appearance PBRAppearance {
                baseColor 0 0.8 0
                roughness 1
                metalness 0
                }
                geometry Cylinder {
                height 0.02
                radius 0.04
                }
            }
            ]
            name "solid(1)"
            boundingObject USE WHEEL
            physics DEF WHEEL_PH Physics {
            }
        }
        }
        HingeJoint {
        jointParameters HingeJointParameters {
            axis 0 1 0
            anchor -0.05 0.06 0
        }
        device [
            RotationalMotor {
            name "wheel3"
            }
        ]
        endPoint DEF Wheel3 Solid {
            translation -0.05 0.06 0
            rotation 1 0 0 1.5707996938995747
            children [
            DEF WHEEL Shape {
                appearance PBRAppearance {
                baseColor 0 0.8 0
                roughness 1
                metalness 0
                }
                geometry Cylinder {
                height 0.02
                radius 0.04
                }
            }
            ]
            name "solid(2)"
            boundingObject USE WHEEL
            physics DEF WHEEL_PH Physics {
            }
        }
        }
        HingeJoint {
        jointParameters HingeJointParameters {
            axis 0 1 0
            anchor -0.05 -0.06 0
        }
        device [
            RotationalMotor {
            name "wheel4"
            }
        ]
        endPoint DEF Wheel4 Solid {
            translation -0.05 -0.06 0
            rotation 1 0 0 1.5707996938995747
            children [
            DEF WHEEL Shape {
                appearance PBRAppearance {
                baseColor 0 0.8 0
                roughness 1
                metalness 0
                }
                geometry Cylinder {
                height 0.02
                radius 0.04
                }
            }
            ]
            name "solid(3)"
            boundingObject USE WHEEL
            physics DEF WHEEL_PH Physics {
            }
        }
        }
    ]
    boundingObject USE BODY
    physics Physics {
    }
    controller "four_wheeled_collision_avoidance"
    }
}