#VRML_SIM R2023b utf8

EXTERNPROTO "https://raw.githubusercontent.com/cyberbotics/webots/R2023b/projects/objects/backgrounds/protos/TexturedBackground.proto"
EXTERNPROTO "https://raw.githubusercontent.com/cyberbotics/webots/R2023b/projects/objects/backgrounds/protos/TexturedBackgroundLight.proto"
EXTERNPROTO "https://raw.githubusercontent.com/cyberbotics/webots/R2023b/projects/objects/factory/containers/protos/WoodenBox.proto"
EXTERNPROTO "https://raw.githubusercontent.com/cyberbotics/webots/R2023b/projects/objects/floors/protos/Floor.proto"
EXTERNPROTO "https://raw.githubusercontent.com/cyberbotics/webots/R2023b/projects/appearances/protos/OldSteel.proto"

WorldInfo {
  basicTimeStep 16
}
Viewpoint {
  orientation -0.4749395495623147 0.6170037148428772 0.6274861274415836 1.773740992148846
  position -0.1632703617332028 -0.7247241919231202 1.9113353560431665
}
TexturedBackground {
}
TexturedBackgroundLight {
}
Floor {
  size 1 1
}
WoodenBox {
  translation 0.42959 0.433011 0.05
  size 0.1 0.1 0.1
}
WoodenBox {
  translation -0.430998 0.428838 0.05
  name "wooden box(1)"
  size 0.1 0.1 0.1
}
DEF WALL1 Solid {
  translation 0 0.51 0.025
  children [
    DEF WALL Shape {
      appearance OldSteel {
      }
      geometry Box {
        size 1 0.02 0.05
      }
    }
  ]
  name "solid(2)"
  boundingObject USE WALL
}
DEF WALL2 Solid {
  translation 0 -0.51 0.025
  children [
    USE WALL
  ]
  name "solid(3)"
  boundingObject USE WALL
}
DEF WALL3 Solid {
  translation 0.51 0 0.025
  rotation 0 0 1 1.5707996938995747
  children [
    USE WALL
  ]
  name "solid(4)"
  boundingObject USE WALL
}
DEF WALL4 Solid {
  translation -0.51 0 0.025
  rotation 0 0 1 1.5707996938995747
  children [
    USE WALL
  ]
  name "solid(5)"
  boundingObject USE WALL
}
Robot {
  translation 0 0 0.04
  children [
    DistanceSensor {
      translation 0.1 0.03 0
      rotation 0 0 1 0.3
      children [
        Shape {
          geometry DEF DS Box {
            size 0.01 0.01 0.01
          }
        }
      ]
      name "ds_left"
      boundingObject USE DS
      physics Physics {
      }
    }
    DistanceSensor {
      translation 0.1 -0.03 0
      rotation 0 0 1 -0.3
      children [
        Shape {
          geometry DEF DS Box {
            size 0.01 0.01 0.01
          }
        }
      ]
      name "ds_right"
      boundingObject USE DS
      physics Physics {
      }
    }
    DEF BODY Shape {
      appearance PBRAppearance {
        baseColor 0.7 0 0
        roughness 1
        metalness 0
      }
      geometry Box {
        size 0.2 0.1 0.05
      }
    }
    HingeJoint {
      jointParameters HingeJointParameters {
        axis 0 1 0
        anchor 0.05 0.06 0
      }
      device [
        RotationalMotor {
          name "wheel1"
        }
      ]
      endPoint DEF Wheel1 Solid {
        translation 0.05 0.06 0
        rotation 1 0 0 1.5707996938995747
        children [
          DEF WHEEL Shape {
            appearance PBRAppearance {
              baseColor 0 0.8 0
              roughness 1
              metalness 0
            }
            geometry Cylinder {
              height 0.02
              radius 0.04
            }
          }
        ]
        boundingObject USE WHEEL
        physics DEF WHEEL_PH Physics {
        }
      }
    }
    HingeJoint {
      jointParameters HingeJointParameters {
        axis 0 1 0
        anchor 0.05 -0.06 0
      }
      device [
        RotationalMotor {
          name "wheel2"
        }
      ]
      endPoint DEF Wheel2 Solid {
        translation 0.05 -0.06 0
        rotation 1 0 0 1.5707996938995747
        children [
          DEF WHEEL Shape {
            appearance PBRAppearance {
              baseColor 0 0.8 0
              roughness 1
              metalness 0
            }
            geometry Cylinder {
              height 0.02
              radius 0.04
            }
          }
        ]
        name "solid(1)"
        boundingObject USE WHEEL
        physics DEF WHEEL_PH Physics {
        }
      }
    }
    HingeJoint {
      jointParameters HingeJointParameters {
        axis 0 1 0
        anchor -0.05 0.06 0
      }
      device [
        RotationalMotor {
          name "wheel3"
        }
      ]
      endPoint DEF Wheel3 Solid {
        translation -0.05 0.06 0
        rotation 1 0 0 1.5707996938995747
        children [
          DEF WHEEL Shape {
            appearance PBRAppearance {
              baseColor 0 0.8 0
              roughness 1
              metalness 0
            }
            geometry Cylinder {
              height 0.02
              radius 0.04
            }
          }
        ]
        name "solid(2)"
        boundingObject USE WHEEL
        physics DEF WHEEL_PH Physics {
        }
      }
    }
    HingeJoint {
      jointParameters HingeJointParameters {
        axis 0 1 0
        anchor -0.05 -0.06 0
      }
      device [
        RotationalMotor {
          name "wheel4"
        }
      ]
      endPoint DEF Wheel4 Solid {
        translation -0.05 -0.06 0
        rotation 1 0 0 1.5707996938995747
        children [
          DEF WHEEL Shape {
            appearance PBRAppearance {
              baseColor 0 0.8 0
              roughness 1
              metalness 0
            }
            geometry Cylinder {
              height 0.02
              radius 0.04
            }
          }
        ]
        name "solid(3)"
        boundingObject USE WHEEL
        physics DEF WHEEL_PH Physics {
        }
      }
    }
  ]
  boundingObject USE BODY
  physics Physics {
  }
  controller "four_wheeled_collision_avoidance"
}
