#VRML_SIM R2023b utf8

EXTERNPROTO "https://raw.githubusercontent.com/cyberbotics/webots/R2023b/projects/objects/backgrounds/protos/TexturedBackground.proto"
EXTERNPROTO "https://raw.githubusercontent.com/cyberbotics/webots/R2023b/projects/objects/backgrounds/protos/TexturedBackgroundLight.proto"
EXTERNPROTO "https://raw.githubusercontent.com/cyberbotics/webots/R2023b/projects/objects/floors/protos/Floor.proto"
EXTERNPROTO "https://raw.githubusercontent.com/cyberbotics/webots/R2023b/projects/robots/nvidia/jetbot/protos/JetBotRaspberryPiCamera.proto"

WorldInfo {
  basicTimeStep 16
  contactProperties [
    ContactProperties {
      material2 "steering_wheel"
      frictionRotation 1 1
    }
  ]
}
Viewpoint {
  orientation -0.49308100132475946 0.49928398748826736 0.7124511393565093 1.8916912886598203
  position -0.40371147712447314 -4.746727536055568 13.620462346277812
  follow "robot"
  followType "None"
}
TexturedBackground {
}
TexturedBackgroundLight {
}
DEF FLOOR Floor {
  size 5 5
  tileSize 5 5
  appearance PBRAppearance {
    baseColorMap ImageTexture {
      url [
        "../textures/EasyCurve.png"
      ]
    }
    roughness 1
    metalness 0
  }
}
DEF ROBOT Robot {
  translation 0 -2 0.04
  rotation 0 0 -1 -1.5707953071795862
  children [
    JetBotRaspberryPiCamera {
      translation 0.11 0 0.07
      rotation 0 1 0 0.261799
    }
    DistanceSensor {
      translation 0.1 0.03 0
      rotation 0 0 1 0.3
      children [
        Shape {
          geometry DEF DS Box {
            size 0.01 0.01 0.01
          }
        }
      ]
      name "ds_left"
      boundingObject USE DS
      physics Physics {
      }
    }
    DistanceSensor {
      translation 0.1 -0.03 0
      rotation 0 0 1 -0.3
      children [
        Shape {
          geometry DEF DS Box {
            size 0.01 0.01 0.01
          }
        }
      ]
      name "ds_right"
      boundingObject USE DS
      physics Physics {
      }
    }
    DEF BODY Shape {
      appearance PBRAppearance {
        baseColor 0.7 0 0
        roughness 1
        metalness 0
      }
      geometry Box {
        size 0.2 0.08 0.05
      }
    }
    Hinge2Joint {
      jointParameters HingeJointParameters {
        axis 0 0 1
        anchor 0.075 0.0725 0
        minStop -0.5
        maxStop 0.5
      }
      jointParameters2 JointParameters {
        axis 0 1 0
      }
      device [
        RotationalMotor {
          name "left_steer"
        }
      ]
      device2 [
        RotationalMotor {
          maxTorque 0
        }
      ]
      endPoint DEF Wheel1 Solid {
        translation 0.075 0.0725 0
        rotation 1 1.1172170342405966e-14 7.81119683140549e-15 1.570799693899233
        children [
          DEF WHEEL Shape {
            appearance PBRAppearance {
              baseColor 0 0.8 0
              baseColorMap ImageTexture {
                url [
                  "../textures/red_brick_wall.jpg"
                ]
              }
              roughness 1
              metalness 0
            }
            geometry Cylinder {
              height 0.025
              radius 0.034
            }
          }
        ]
        name "solid(4)"
        contactMaterial "steering_wheel"
        boundingObject USE WHEEL
        physics DEF WHEEL_PH Physics {
        }
      }
    }
    Hinge2Joint {
      jointParameters HingeJointParameters {
        axis 0 0 1
        anchor 0.075 -0.0725 0
        minStop -0.5
        maxStop 0.5
      }
      jointParameters2 JointParameters {
        axis 0 1 0
      }
      device [
        RotationalMotor {
          name "right_steer"
        }
      ]
      device2 [
        RotationalMotor {
          maxTorque 0
        }
      ]
      endPoint DEF Wheel2 Solid {
        translation 0.075 -0.0725 0
        rotation 1 7.75231846332936e-15 1.583828101242226e-14 1.570799693899286
        children [
          USE WHEEL
        ]
        name "solid(5)"
        contactMaterial "steering_wheel"
        boundingObject USE WHEEL
        physics DEF WHEEL_PH Physics {
        }
      }
    }
    HingeJoint {
      jointParameters HingeJointParameters {
        axis 0 1 0
        anchor -0.075 0.0825 0
      }
      device [
        RotationalMotor {
          name "wheel3"
        }
      ]
      endPoint DEF Wheel3 Solid {
        translation -0.07499999999999996 0.08250000000000068 9.8486530224623e-17
        rotation 1 -3.7363497990111923e-10 3.7363317429783157e-10 1.570799693899308
        children [
          USE WHEEL
        ]
        name "solid(2)"
        boundingObject USE WHEEL
        physics DEF WHEEL_PH Physics {
        }
      }
    }
    HingeJoint {
      jointParameters HingeJointParameters {
        axis 0 1 0
        anchor -0.075 -0.0825 0
      }
      device [
        RotationalMotor {
          name "wheel4"
        }
      ]
      endPoint DEF Wheel4 Solid {
        translation -0.0749999999999999 -0.0825000000000029 -9.579680973932131e-17
        rotation 1 -7.580906771508269e-10 -9.109970634271003e-10 1.5707996891550322
        children [
          USE WHEEL
        ]
        name "solid(3)"
        boundingObject USE WHEEL
        physics DEF WHEEL_PH Physics {
        }
      }
    }
  ]
  boundingObject USE BODY
  physics Physics {
  }
  controller "q_learning_controller"
  supervisor TRUE
}
