#VRML_SIM R2023b utf8

EXTERNPROTO "https://raw.githubusercontent.com/cyberbotics/webots/R2023b/projects/objects/backgrounds/protos/TexturedBackground.proto"
EXTERNPROTO "https://raw.githubusercontent.com/cyberbotics/webots/R2023b/projects/objects/backgrounds/protos/TexturedBackgroundLight.proto"
EXTERNPROTO "https://raw.githubusercontent.com/cyberbotics/webots/R2023b/projects/objects/floors/protos/Floor.proto"
EXTERNPROTO "https://raw.githubusercontent.com/cyberbotics/webots/R2023b/projects/robots/nvidia/jetbot/protos/JetBotRaspberryPiCamera.proto"

WorldInfo {
  basicTimeStep 16
  contactProperties [
    ContactProperties {
      material2 "steering_wheel"
      frictionRotation 1 1
    }
  ]
}
Viewpoint {
  orientation -0.5773502691896258 0.5773502691896258 0.5773502691896258 2.0944
  position 8.443091496276215e-06 8.443115370844006e-06 12.557469734547743
  follow "robot"
  followType "None"
}
TexturedBackground {
}
TexturedBackgroundLight {
}
DEF FLOOR Floor {
  size 5 5
  tileSize 5 5
  appearance PBRAppearance {
    baseColorMap ImageTexture {
      url [
        "../textures/RightAngle.png"
      ]
    }
    roughness 1
    metalness 0
  }
}
DEF ROBOT Robot {
  translation 0 -2 0.04
  rotation 0 0 -1 -1.5707953071795862
  children [
    JetBotRaspberryPiCamera {
      translation 0.11 0 0.07
      rotation 0 1 0 0.261799
    }
    DEF BODY Shape {
      appearance PBRAppearance {
        baseColor 0.7 0 0
        roughness 1
        metalness 0
      }
      geometry Box {
        size 0.2 0.05 0.05
      }
    }
    Hinge2Joint {
      jointParameters HingeJointParameters {
        axis 0 0 1
        anchor 0.075 0.0725 0
        minStop -0.5
        maxStop 0.5
        dampingConstant 10
      }
      jointParameters2 JointParameters {
        axis 0 1 0
      }
      device [
        RotationalMotor {
          name "left_steer"
        }
      ]
      device2 [
        RotationalMotor {
          maxTorque 0
        }
      ]
      endPoint DEF Wheel1 Solid {
        translation 0.075 0.0725 0
        rotation 1 1.1363525038652706e-14 7.379422132182069e-15 1.5707996938992326
        children [
          DEF WHEEL Shape {
            appearance PBRAppearance {
              baseColor 0 0.8 0
              baseColorMap ImageTexture {
                url [
                  "../textures/red_brick_wall.jpg"
                ]
              }
              roughness 1
              metalness 0
            }
            geometry Cylinder {
              height 0.025
              radius 0.034
            }
          }
        ]
        name "solid(4)"
        contactMaterial "steering_wheel"
        boundingObject USE WHEEL
        physics DEF WHEEL_PH Physics {
        }
      }
    }
    Hinge2Joint {
      jointParameters HingeJointParameters {
        axis 0 0 1
        anchor 0.075 -0.0725 0
        minStop -0.5
        maxStop 0.5
        dampingConstant 10
      }
      jointParameters2 JointParameters {
        axis 0 1 0
      }
      device [
        RotationalMotor {
          name "right_steer"
        }
      ]
      device2 [
        RotationalMotor {
          maxTorque 0
        }
      ]
      endPoint DEF Wheel2 Solid {
        translation 0.075 -0.0725 0
        rotation 1 8.360728266780531e-15 1.613267285280187e-14 1.5707996938992845
        children [
          USE WHEEL
        ]
        name "solid(5)"
        contactMaterial "steering_wheel"
        boundingObject USE WHEEL
        physics DEF WHEEL_PH Physics {
        }
      }
    }
    HingeJoint {
      jointParameters HingeJointParameters {
        axis 0 1 0
        anchor -0.075 0.0825 0
      }
      device [
        RotationalMotor {
          name "wheel3"
        }
      ]
      endPoint DEF Wheel3 Solid {
        translation -0.07499999999999996 0.08250000000000068 9.964195673689537e-17
        rotation 1 -3.7363533317132805e-10 3.736332135500773e-10 1.5707996938993067
        children [
          USE WHEEL
        ]
        name "solid(2)"
        boundingObject USE WHEEL
        physics DEF WHEEL_PH Physics {
        }
      }
    }
    HingeJoint {
      jointParameters HingeJointParameters {
        axis 0 1 0
        anchor -0.075 -0.0825 0
      }
      device [
        RotationalMotor {
          name "wheel4"
        }
      ]
      endPoint DEF Wheel4 Solid {
        translation -0.0749999999999999 -0.0825000000000029 -9.592392350413505e-17
        rotation 1 -7.580903533198017e-10 -9.109971615577141e-10 1.5707996891550329
        children [
          USE WHEEL
        ]
        name "solid(3)"
        boundingObject USE WHEEL
        physics DEF WHEEL_PH Physics {
        }
      }
    }
  ]
  boundingObject USE BODY
  physics Physics {
  }
  controller "fuzzy_bayesian"
  supervisor TRUE
}
