#VRML_SIM R2023b utf8

EXTERNPROTO "https://raw.githubusercontent.com/cyberbotics/webots/R2023b/projects/objects/backgrounds/protos/TexturedBackground.proto"
EXTERNPROTO "https://raw.githubusercontent.com/cyberbotics/webots/R2023b/projects/objects/backgrounds/protos/TexturedBackgroundLight.proto"
EXTERNPROTO "https://raw.githubusercontent.com/cyberbotics/webots/R2023b/projects/objects/floors/protos/Floor.proto"
EXTERNPROTO "https://raw.githubusercontent.com/cyberbotics/webots/R2023b/projects/appearances/protos/OldSteel.proto"
EXTERNPROTO "https://raw.githubusercontent.com/cyberbotics/webots/R2023b/projects/robots/nvidia/jetbot/protos/JetBotRaspberryPiCamera.proto"

WorldInfo {
  basicTimeStep 16
  contactProperties [
    ContactProperties {
      material2 "steering_wheel"
      frictionRotation 1 1
    }
  ]
}
Viewpoint {
  orientation -0.41350078350350117 0.23800536746614873 0.8788461452946664 2.2049633876446406
  position 2.180650233995734 -4.065157977925139 4.517575094169417
  follow "robot"
  followType "None"
}
TexturedBackground {
}
TexturedBackgroundLight {
}
Floor {
  size 5 5
  tileSize 5 5
  appearance PBRAppearance {
    baseColorMap ImageTexture {
      url [
        "../textures/gimp_track.png"
      ]
    }
    roughness 1
    metalness 0
  }
}
DEF WALL1 Solid {
  translation 0 2.51 0.025
  children [
    DEF WALL Shape {
      appearance OldSteel {
      }
      geometry Box {
        size 3 0.02 0.05
      }
    }
  ]
  name "solid(2)"
  boundingObject USE WALL
}
DEF WALL2 Solid {
  translation 0 -2.51 0.025
  children [
    USE WALL
  ]
  name "solid(3)"
  boundingObject USE WALL
}
DEF WALL3 Solid {
  translation 2.51 0 0.025
  rotation 0 0 1 1.5707996938995747
  children [
    USE WALL
  ]
  name "solid(4)"
  boundingObject USE WALL
}
DEF WALL4 Solid {
  translation -2.51 0 0.025
  rotation 0 0 1 1.5707996938995747
  children [
    USE WALL
  ]
  name "solid(5)"
  boundingObject USE WALL
}
DEF ROBOT Robot {
  translation 0.302759 -1.11344 0.04
  rotation 0 0 1 3.14159
  children [
    JetBotRaspberryPiCamera {
      translation 0.11 0 0.07
      rotation 0 1 0 0.261799
    }
    DistanceSensor {
      translation 0.1 0.03 0
      rotation 0 0 1 0.3
      children [
        Shape {
          geometry DEF DS Box {
            size 0.01 0.01 0.01
          }
        }
      ]
      name "ds_left"
      boundingObject USE DS
      physics Physics {
      }
    }
    DistanceSensor {
      translation 0.1 -0.03 0
      rotation 0 0 1 -0.3
      children [
        Shape {
          geometry DEF DS Box {
            size 0.01 0.01 0.01
          }
        }
      ]
      name "ds_right"
      boundingObject USE DS
      physics Physics {
      }
    }
    DEF BODY Shape {
      appearance PBRAppearance {
        baseColor 0.7 0 0
        roughness 1
        metalness 0
      }
      geometry Box {
        size 0.2 0.08 0.05
      }
    }
    Hinge2Joint {
      jointParameters HingeJointParameters {
        axis 0 0 1
        anchor 0.075 0.0725 0
        minStop -0.5
        maxStop 0.5
      }
      jointParameters2 JointParameters {
        axis 0 1 0
      }
      device [
        RotationalMotor {
          name "left_steer"
        }
      ]
      device2 [
        RotationalMotor {
          maxTorque 0
        }
      ]
      endPoint DEF Wheel1 Solid {
        translation 0.075 0.0725 0
        rotation 1 1.1442029529419926e-14 8.478485002932089e-15 1.5707996938993514
        children [
          DEF WHEEL Shape {
            appearance PBRAppearance {
              baseColor 0 0.8 0
              baseColorMap ImageTexture {
                url [
                  "../textures/red_brick_wall.jpg"
                ]
              }
              roughness 1
              metalness 0
            }
            geometry Cylinder {
              height 0.025
              radius 0.034
            }
          }
        ]
        name "solid(4)"
        contactMaterial "steering_wheel"
        boundingObject USE WHEEL
        physics DEF WHEEL_PH Physics {
        }
      }
    }
    Hinge2Joint {
      jointParameters HingeJointParameters {
        axis 0 0 1
        anchor 0.075 -0.0725 0
        minStop -0.5
        maxStop 0.5
      }
      jointParameters2 JointParameters {
        axis 0 1 0
      }
      device [
        RotationalMotor {
          name "right_steer"
        }
      ]
      device2 [
        RotationalMotor {
          maxTorque 0
        }
      ]
      endPoint DEF Wheel2 Solid {
        translation 0.075 -0.0725 0
        rotation 1 9.305235421331215e-15 1.2482214032094181e-14 1.5707996938993969
        children [
          USE WHEEL
        ]
        name "solid(5)"
        contactMaterial "steering_wheel"
        boundingObject USE WHEEL
        physics DEF WHEEL_PH Physics {
        }
      }
    }
    HingeJoint {
      jointParameters HingeJointParameters {
        axis 0 1 0
        anchor -0.075 0.0825 0
      }
      device [
        RotationalMotor {
          name "wheel3"
        }
      ]
      endPoint DEF Wheel3 Solid {
        translation -0.075 0.0825 0
        rotation 1 -2.2766302322687305e-15 0 1.5707996938994144
        children [
          USE WHEEL
        ]
        name "solid(2)"
        boundingObject USE WHEEL
        physics DEF WHEEL_PH Physics {
        }
      }
    }
    HingeJoint {
      jointParameters HingeJointParameters {
        axis 0 1 0
        anchor -0.075 -0.0825 0
      }
      device [
        RotationalMotor {
          name "wheel4"
        }
      ]
      endPoint DEF Wheel4 Solid {
        translation -0.075 -0.0825 0
        rotation -1 8.345475219743943e-10 8.345355132405438e-10 4.712385618024479
        children [
          USE WHEEL
        ]
        name "solid(3)"
        boundingObject USE WHEEL
        physics DEF WHEEL_PH Physics {
        }
      }
    }
  ]
  boundingObject USE BODY
  physics Physics {
  }
  controller "RL_controller"
  supervisor TRUE
}
